Workbook

Sheet Expense report
A1: Expense Report 费用报销单 | I1: 汇率： | J1: 6.8175
A2: Department / 报销部门：
A3: Date / 填表日期：
A4: Employee: / 申请人：
A5: Category 类别 | B5: Date 日期 | C5: Details 详细信息 | D5: Purpose 事由 | E5: Project No. 项目号 | F5: Amount(USD) 金额（美元) | G5: 参考金额（人民币） | H5: 备 注 （注）
A6: Travel expense-Transportation 交通費 | G6: =F6*$J$1
G7: =F7*$J$1
G8: =F8*$J$1
G9: =F9*$J$1
G10: =F10*$J$1
G11: =F11*$J$1
G12: =F12*$J$1
G13: =F13*$J$1
G14: =F14*$J$1
G15: =F15*$J$1
G16: =F16*$J$1
G17: =F17*$J$1
G18: =F18*$J$1
... G46: =F46*$J$1
A47: Subtotal: 小計: | F47: =SUM(F6:F46) | G47: =F47*$J$1
A48: Travel expense - Lodging 住宿 | G48: =F48*$J$1
G49: =F49*$J$1
G50: =F50*$J$1
G51: =F51*$J$1
A52: Subtotal: 小計: | F52: =SUM(F49:F51) | G52: =F52*$J$1
A53: Travel expense - Meals 餐费 | G53: =F53*$J$1
G54: =F54*$J$1
A55: Subtotal: 小計: | F55: =SUM(F53:F54) | G55: =F55*$J$1
A56: Advertising and publicity fee 广告宣传费用 | G56: =F56*$J$1
G57: =F57*$J$1
A58: Subtotal: 小計: | F58: =SUM(F56:F57) | G58: =F58*$J$1
A59: Office Cost 办公费 | G59: =F59*$J$1
G60: =F60*$J$1
G61: =F61*$J$1
G62: =F62*$J$1
G63: =F63*$J$1
G64: =F64*$J$1
A65: Subtotal: 小計: | F65: =SUM(F59:F64) | G65: =F65*$J$1
A66: Entertainment Expenses 招待费 | G66: =F66*$J$1
G67: =F67*$J$1
...

Sheet Receipt and Payment of expenses
A1: 序号 | B1: Date日期 | C1: Expense支出 | D1: Receipt发票 | E1: Proof of Payment银行付款凭证

Sheet Mileage Reimbursement
A1: Purpose 事由 | B1: Companion 同行人 | C1: Travel date 日期 | D1: Miles 公里數 | E1: Mileage Rate 油費補助0.585USD/mile | F1: Customer 客戶 | G1: Departure and destination 行程 | H1: Map of Route 路線地圖 | I1: Parking Fee 停車費 | J1: Receipt Of Parking 停車費收據 | K1: Toll Fee 高速公路過路費 | L1: Receipt Of Toll Fee 收據
E2: =D2*0.585
E3: =D3*0.585
E4: =D4*0.585
E5: =D5*0.585
E6: =D6*0.585
E7: =D7*0.585
E8: =D8*0.585
E9: =D9*0.585
E10: =D10*0.585
E11: =D11*0.585
E12: =D12*0.585
E13: =D13*0.585
... E16: =D16*0.585
A17: Sub Total | E17: =E16+I16+K16

Sheet 面单
A1: 费 用 报 销 单Expense statement
A2: 报销部门：国际营销 2023年 月 日 填 单据及附件共 页 To submit an expense account department：Front End International Marketing Department Date：
A3: 用途 With the way | C3: 金额(美金USD) | D3: 金额（人民币） Amount (RMB) | E3: 备 注 To prepare note
A4: ='Expense report'!A6 | C4: ='Expense report'!F47 | D4: ='Expense report'!G47
A5: ='Expense report'!A48 | C5: ='Expense report'!F52 | D5: ='Expense report'!G52
A6: ='Expense report'!A53 | C6: ='Expense report'!F55 | D6: ='Expense report'!G55
A7: ='Expense report'!A56 | C7: ='Expense report'!F58 | D7: ='Expense report'!G58
A8: ='Expense report'!A59 | C8: ='Expense report'!F65 | D8: ='Expense report'!G65
A9: ='Expense report'!A66 | C9: ='Expense report'!F69 | D9: ='Expense report'!G69
A10: Mileage Reimbursment 私车公用 | C10: ='Mileage Reimbursement'!E17 | E10: 部 门 审 核 Department audit | G10: 领 导 审 批 Leadership audit
A11: 合 计 | C11: =SUM(C4:C10) | D11: =SUM(D4:D10)
E12: 原借款： 元 The original loan： | G12: 应退余款： 元 Shall refund the balance：
A13: 领导审批 会计主管 会计 出纳 报销人 领款人 Leadership approva： accounting supervisor； accounting； cashier； People concerned： payee：
